Epoch [1/10]:   0%|                                                       | 0/938366 [00:00<?, ?it/s]
  0%|                                                                     | 0/938366 [00:00<?, ?it/s]
Traceback (most recent call last):                                        | 0/938366 [00:00<?, ?it/s]
  File "/global/u2/s/salmab/ARNIQA/main.py", line 129, in <module>
    main()
  File "/global/u2/s/salmab/ARNIQA/main.py", line 114, in main
    train(args, model, train_dataloader, optimizer, lr_scheduler, scaler, logger, device)
  File "/global/u2/s/salmab/ARNIQA/train.py", line 74, in train
    for i, batch in enumerate(tqdm(train_dataloader)):
  File "/global/homes/s/salmab/.conda/envs/ARNIQA/lib/python3.10/site-packages/tqdm/std.py", line 1182, in __iter__
    for obj in iterable:
  File "/global/homes/s/salmab/.conda/envs/ARNIQA/lib/python3.10/site-packages/torch/utils/data/dataloader.py", line 630, in __next__
    data = self._next_data()
  File "/global/homes/s/salmab/.conda/envs/ARNIQA/lib/python3.10/site-packages/torch/utils/data/dataloader.py", line 1345, in _next_data
    return self._process_data(data)
  File "/global/homes/s/salmab/.conda/envs/ARNIQA/lib/python3.10/site-packages/torch/utils/data/dataloader.py", line 1371, in _process_data
    data.reraise()
  File "/global/homes/s/salmab/.conda/envs/ARNIQA/lib/python3.10/site-packages/torch/_utils.py", line 694, in reraise
    raise exception
FileNotFoundError: Caught FileNotFoundError in DataLoader worker process 0.
Original Traceback (most recent call last):
  File "/global/homes/s/salmab/.conda/envs/ARNIQA/lib/python3.10/site-packages/torch/utils/data/_utils/worker.py", line 308, in _worker_loop
    data = fetcher.fetch(index)
  File "/global/homes/s/salmab/.conda/envs/ARNIQA/lib/python3.10/site-packages/torch/utils/data/_utils/fetch.py", line 51, in fetch
    data = [self.dataset[idx] for idx in possibly_batched_index]
  File "/global/homes/s/salmab/.conda/envs/ARNIQA/lib/python3.10/site-packages/torch/utils/data/_utils/fetch.py", line 51, in <listcomp>
    data = [self.dataset[idx] for idx in possibly_batched_index]
  File "/global/u2/s/salmab/ARNIQA/data/dataset_decam.py", line 72, in __getitem__
    hdul_B = fits.open(img_B_path)
  File "/global/homes/s/salmab/.conda/envs/ARNIQA/lib/python3.10/site-packages/astropy/io/fits/hdu/hdulist.py", line 222, in fitsopen
    return HDUList.fromfile(
  File "/global/homes/s/salmab/.conda/envs/ARNIQA/lib/python3.10/site-packages/astropy/io/fits/hdu/hdulist.py", line 486, in fromfile
    return cls._readfrom(
  File "/global/homes/s/salmab/.conda/envs/ARNIQA/lib/python3.10/site-packages/astropy/io/fits/hdu/hdulist.py", line 1157, in _readfrom
    fileobj = _File(
  File "/global/homes/s/salmab/.conda/envs/ARNIQA/lib/python3.10/site-packages/astropy/io/fits/file.py", line 218, in __init__
    self._open_filename(fileobj, mode, overwrite)
  File "/global/homes/s/salmab/.conda/envs/ARNIQA/lib/python3.10/site-packages/astropy/io/fits/file.py", line 641, in _open_filename
    self._file = open(self.name, IO_FITS_MODES[mode])
FileNotFoundError: [Errno 2] No such file or directory: '/global/cfs/cdirs/cosmo/work/legacysurvey/dr10/images/decam/CP/V3.9.2/CP20150903/c4d_150903_084458_ooi_Y_v1.fits.fz'