  0%|                                                                         | 0/25 [00:01<?, ?it/s]
Traceback (most recent call last):                                            | 0/25 [00:00<?, ?it/s]
  File "/global/u2/s/salmab/ARNIQA/main.py", line 129, in <module>
    main()
  File "/global/u2/s/salmab/ARNIQA/main.py", line 114, in main
    train(args, model, train_dataloader, optimizer, lr_scheduler, scaler, logger, device)
  File "/global/u2/s/salmab/ARNIQA/train.py", line 74, in train
    for i, batch in enumerate(tqdm(train_dataloader)):
  File "/global/homes/s/salmab/.conda/envs/ARNIQA/lib/python3.10/site-packages/tqdm/std.py", line 1182, in __iter__
    for obj in iterable:
  File "/global/homes/s/salmab/.conda/envs/ARNIQA/lib/python3.10/site-packages/torch/utils/data/dataloader.py", line 630, in __next__
    data = self._next_data()
  File "/global/homes/s/salmab/.conda/envs/ARNIQA/lib/python3.10/site-packages/torch/utils/data/dataloader.py", line 1345, in _next_data
    return self._process_data(data)
  File "/global/homes/s/salmab/.conda/envs/ARNIQA/lib/python3.10/site-packages/torch/utils/data/dataloader.py", line 1371, in _process_data
    data.reraise()
  File "/global/homes/s/salmab/.conda/envs/ARNIQA/lib/python3.10/site-packages/torch/_utils.py", line 694, in reraise
    raise exception
IndexError: Caught IndexError in DataLoader worker process 0.
Original Traceback (most recent call last):
  File "/global/homes/s/salmab/.conda/envs/ARNIQA/lib/python3.10/site-packages/torch/utils/data/_utils/worker.py", line 308, in _worker_loop
    data = fetcher.fetch(index)
  File "/global/homes/s/salmab/.conda/envs/ARNIQA/lib/python3.10/site-packages/torch/utils/data/_utils/fetch.py", line 51, in fetch
    data = [self.dataset[idx] for idx in possibly_batched_index]
  File "/global/homes/s/salmab/.conda/envs/ARNIQA/lib/python3.10/site-packages/torch/utils/data/_utils/fetch.py", line 51, in <listcomp>
    data = [self.dataset[idx] for idx in possibly_batched_index]
  File "/global/u2/s/salmab/ARNIQA/data/dataset_decam.py", line 106, in __getitem__
    img_B_orig, distort_functions_B, distort_values_B = distort_images(img_B_orig,
  File "/global/u2/s/salmab/ARNIQA/utils/utils_data.py", line 123, in distort_images
    image = distortion(image, value)
  File "/global/u2/s/salmab/ARNIQA/utils/distortions.py", line 268, in mean_shift
    x = x[[2, 1, 0], :, :]
IndexError: index 2 is out of bounds for dimension 0 with size 1
Saving checkpoints in folder:  /global/u2/s/salmab/ARNIQA/experiments/Testing_Try/pretrain